Workbook

Sheet EnergyIntensity_Cu
A1: Company | B1: Production site | C1: Main product | D1: Key | E1: Total energy consumption | F1: Total Value | G1: Unit | H1: Annual Cu production (t) | I1: Allocation factors Cu (%) | J1: Energy intensity (GJ/t Cu) | K1: Agg | L1: Moyenne energy | M1: Moyenne elec/fuel
A2: Freeport | B2: El Abra | C2: Cu cathode | D2: =CONCATENATE(B2,"_",C2) -> El Abra_Cu cathode | E2: Electricity consumption | F2: =SUM(EnergyData_Processed!G2) -> 2398000 | G2: GJ | H2: =VLOOKUP(D2,ProductionData_Processed!$E:$J,5,FALSE) -> 98429 | I2: =VLOOKUP(D2,ProductionData_Processed!$E:$L,8,FALSE) -> 1 | J2: =F2/H2*I2 -> 24.362739 | K2: =SUM(J2:J3) -> 35.747595 | L2: =AVERAGE(K2:K22) -> 35.200469 | M2: =AVERAGE(J2,J4,J6,J8,J10,J12,J14,J16,J18,J20) -> 14.75896
A3: Freeport | B3: El Abra | C3: Cu cathode | D3: =CONCATENATE(B3,"_",C3) -> El Abra_Cu cathode | E3: Fuel consumption | F3: =SUM(EnergyData_Processed!G3:G5) -> 1120600 | G3: GJ | H3: =VLOOKUP(D3,ProductionData_Processed!$E:$J,5,FALSE) -> 98429 | I3: =VLOOKUP(D3,ProductionData_Processed!$E:$L,8,FALSE) -> 1 | J3: =F3/H3*I3 -> 11.384856 | M3: =AVERAGE(J3,J5,J7,J9,J11,J13,J15,J17,J19,J21,J22) -> 21.783233
A4: MMG | B4: Kinsevere | C4: Cu cathode | D4: =CONCATENATE(B4,"_",C4) -> Kinsevere_Cu cathode | E4: Electricity consumption | F4: =SUM(EnergyData_Processed!G7) -> 503140 | G4: GJ | H4: =VLOOKUP(D4,ProductionData_Processed!$E:$J,5,FALSE) -> 44068 | I4: =VLOOKUP(D4,ProductionData_Processed!$E:$L,8,FALSE) -> 0.99283836 | J4: =F4/H4*I4 -> 11.335588 | K4: =SUM(J4:J5) -> 37.490462
A5: MMG | B5: Kinsevere | C5: Cu cathode | D5: =CONCATENATE(B5,"_",C5) -> Kinsevere_Cu cathode | E5: Fuel consumption | F5: =SUM(EnergyData_Processed!G6) -> 1160907 | G5: GJ | H5: =VLOOKUP(D5,ProductionData_Processed!$E:$J,5,FALSE) -> 44068 | I5: =VLOOKUP(D5,ProductionData_Processed!$E:$L,8,FALSE) -> 0.99283836 | J5: =F5/H5*I5 -> 26.154874
A6: Central Asia Metals | B6: Kounrad | C6: Cu cathode | D6: =CONCATENATE(B6,"_",C6) -> Kounrad_Cu cathode | E6: Electricity consumption | F6: =SUM(EnergyData_Processed!G10:G11) -> 212373 | G6: GJ | H6: =VLOOKUP(D6,ProductionData_Processed!$E:$J,5,FALSE) -> 13816 | I6: =VLOOKUP(D6,ProductionData_Processed!$E:$L,8,FALSE) -> 1 | J6: =F6/H6*I6 -> 15.371526 | K6: =SUM(J6:J7) -> 34.297119
A7: Central Asia Metals | B7: Kounrad | C7: Cu cathode | D7: =CONCATENATE(B7,"_",C7) -> Kounrad_Cu cathode | E7: Fuel consumption | F7: =SUM(EnergyData_Processed!G8:G9) -> 261476 | G7: GJ | H7: =VLOOKUP(D7,ProductionData_Processed!$E:$J,5,FALSE) -> 13816 | I7: =VLOOKUP(D7,ProductionData_Processed!$E:$L,8,FALSE) -> 1 | J7: =F7/H7*I7 -> 18.925594
A8: Freeport | B8: Safford | C8: Cu cathode | D8: =CONCATENATE(B8,"_",C8) -> Safford_Cu cathode | E8: Electricity consumption | F8: =SUM(EnergyData_Processed!G12) -> 1392000 | G8: GJ | H8: =VLOOKUP(D8,ProductionData_Processed!$E:$J,5,FALSE) -> 111130 | I8: =VLOOKUP(D8,ProductionData_Processed!$E:$L,8,FALSE) -> 1 | J8: =F8/H8*I8 -> 12.525871 | K8: =SUM(J8:J9) -> 39.028165
A9: Freeport | B9: Safford | C9: Cu cathode | D9: =CONCATENATE(B9,"_",C9) -> Safford_Cu cathode | E9: Fuel consumption | F9: =SUM(EnergyData_Processed!G13:G15) -> 2945200 | G9: GJ | H9: =VLOOKUP(D9,ProductionData_Processed!$E:$J,5,FALSE) -> 111130 | I9: =VLOOKUP(D9,ProductionData_Processed!$E:$L,8,FALSE) -> 1 | J9: =F9/H9*I9 -> 26.502295
A10: Freeport | B10: Tyrone | C10: Cu cathode | D10: =CONCATENATE(B10,"_",C10) -> Tyrone_Cu cathode | E10: Electricity consumption | F10: =SUM(EnergyData_Processed!G16) -> 764000 | G10: GJ | H10: =VLOOKUP(D10,ProductionData_Processed!$E:$J,5,FALSE) -> 23133 | I10: =VLOOKUP(D10,ProductionData_Processed!$E:$L,8,FALSE) -> 1 | J10: =F10/H10*I10 -> 33.026412 | K10: =SUM(J10:J11) -> 60.415856
A11: Freeport | B11: Tyrone | C11: Cu cathode | D11: =CONCATENATE(B11,"_",C11) -> Tyrone_Cu cathode | E11: Fuel consumption | F11: =SUM(EnergyData_Processed!G17:G21) -> 633600 | G11: GJ | H11: =VLOOKUP(D11,ProductionData_Processed!$E:$J,5,FALSE) -> 23133 | I11: =VLOOKUP(D11,ProductionData_Processed!$E:$L,8,FALSE) -> 1 | J11: =F11/H11*I11 -> 27.389444
A12: PT Merdeka | B12: Wetar | C12: Cu cathode | D12: =CONCATENATE(B12,"_",C12) -> Wetar_Cu cathode | E12: Electricity consumption | F12: =SUM(EnergyData_Processed!G22) -> 226542.02 | G12: GJ | H12: =VLOOKUP(D12,ProductionData_Processed!$E:$J,5,FALSE) -> 19045 | I12: =VLOOKUP(D12,ProductionData_Processed!$E:$L,8,FALSE) -> 1 | J12: =F12/H12*I12 -> 11.895092 | K12: =SUM(J12:J13) -> 41.018363
A13: PT Merdeka | B13: Wetar | C13: Cu cathode | D13: =CONCATENATE(B13,"_",C13) -> Wetar_Cu cathode | E13: Fuel consumption | F13: =SUM(EnergyData_Processed!G23:G24) -> 554652.69 | G13: GJ | H13: =VLOOKUP(D13,ProductionData_Processed!$E:$J,5,FALSE) -> 19045 | I13: =VLOOKUP(D13,ProductionData_Processed!$E:$L,8,FALSE) -> 1 | J13: =F13/H13*I13 -> 29.123271
A14: Capstone | B14: Cozamin | C14: Cu cathode | D14: =CONCATENATE(B14,"_",C14) -> Cozamin_Cu cathode | E14: Electricity consumption | F14: =SUM(EnergyData_Processed!G84) -> 228707 | G14: GJ | H14: =VLOOKUP(D14,ProductionData_Processed!$E:$J,5,FALSE) -> 24451 | I14: =VLOOKUP(D14,ProductionData_Processed!$E:$L,8,FALSE) -> 0.86435267 | J14: =F14/H14*I14 -> 8.0848843 | K14: =SUM(J14:J15) -> 14.018626
A15: Capstone | B15: Cozamin | C15: Cu cathode | D15: =CONCATENATE(B15,"_",C15) -> Cozamin_Cu cathode | E15: Fuel consumption | F15: =SUM(EnergyData_Processed!G83) -> 167855 | G15: GJ | H15: =VLOOKUP(D15,ProductionData_Processed!$E:$J,5,FALSE) -> 24451 | I15: =VLOOKUP(D15,ProductionData_Processed!$E:$L,8,FALSE) -> 0.86435267 | J15: =F15/H15*I15 -> 5.9337417
A16: Capstone | B16: Mantos Blancos | C16: Cu cathode | D16: =CONCATENATE(B16,"_",C16) -> Mantos Blancos_Cu cathode | E16: Electricity consumption | F16: =F14 -> 228707 | G16: GJ | H16: =VLOOKUP(D16,ProductionData_Processed!$E:$J,5,FALSE) -> 15697 | I16: =VLOOKUP(D16,ProductionData_Processed!$E:$L,8,FALSE) -> 0.30288707 | J16: =F16/H16*I16 -> 4.4130976 | K16: =SUM(J16:J17) -> 7.6520037
A17: Capstone | B17: Mantos Blancos | C17: Cu cathode | D17: =CONCATENATE(B17,"_",C17) -> Mantos Blancos_Cu cathode | E17: Fuel consumption | F17: =F15 -> 167855 | G17: GJ | H17: =VLOOKUP(D17,ProductionData_Processed!$E:$J,5,FALSE) -> 15697 | I17: =VLOOKUP(D17,ProductionData_Processed!$E:$L,8,FALSE) -> 0.30288707 | J17: =F17/H17*I17 -> 3.2389061
A18: Capstone | B18: Mantoverde | C18: Cu cathode | D18: =CONCATENATE(B18,"_",C18) -> Mantoverde_Cu cathode | E18: Electricity consumption | F18: =EnergyData_Processed!G88 -> 691918 | G18: GJ | H18: =VLOOKUP(D18,ProductionData_Processed!$E:$J,5,FALSE) -> 47364 | I18: =VLOOKUP(D18,ProductionData_Processed!$E:$L,8,FALSE) -> 0.96083219 | J18: =F18/H18*I18 -> 14.036337 | K18: =SUM(J18:J19) -> 56.671126
A19: Capstone | B19: Mantoverde | C19: Cu cathode | D19: =CONCATENATE(B19,"_",C19) -> Mantoverde_Cu cathode | E19: Fuel consumption | F19: =SUM(EnergyData_Processed!G87) -> 2101672 | G19: GJ | H19: =VLOOKUP(D19,ProductionData_Processed!$E:$J,5,FALSE) -> 47364 | I19: =VLOOKUP(D19,ProductionData_Processed!$E:$L,8,FALSE) -> 0.96083219 | J19: =F19/H19*I19 -> 42.634788
A20: Capstone | B20: Pinto Valley | C20: Cu cathode | D20: =CONCATENATE(B20,"_",C20) -> Pinto Valley_Cu cathode | E20: Electricity consumption | F20: =F18 -> 691918 | G20: GJ | H20: =VLOOKUP(D20,ProductionData_Processed!$E:$J,5,FALSE) -> 2622 | I20: =VLOOKUP(D20,ProductionData_Processed!$E:$L,8,FALSE) -> 0.04751252 | J20: =F20/H20*I20 -> 12.53805 | K20: =SUM(J20:J21) -> 50.621853
A21: Capstone | B21: Pinto Valley | C21: Cu cathode | D21: =CONCATENATE(B21,"_",C21) -> Pinto Valley_Cu cathode | E21: Fuel consumption | F21: =F19 -> 2101672 | G21: GJ | H21: =VLOOKUP(D21,ProductionData_Processed!$E:$J,5,FALSE) -> 2622 | I21: =VLOOKUP(D21,ProductionData_Processed!$E:$L,8,FALSE) -> 0.04751252 | J21: =F21/H21*I21 -> 38.083803
A22: Minsur | B22: Mina Justa | C22: Cu cathode | D22: =CONCATENATE(B22,"_",C22) -> Mina Justa _Cu cathode | E22: Fuel consumption | F22: =SUM(EnergyData_Processed!G101:G102) -> 1464062.4 | G22: GJ | H22: =VLOOKUP(D22,ProductionData_Processed!$E:$J,5,FALSE) -> 39314 | I22: =VLOOKUP(D22,ProductionData_Processed!$E:$L,8,FALSE) -> 0.27507866 | J22: =F22/H22*I22 -> 10.243993 | K22: =J22 -> 10.243993
A23: PT Amman | B23: Batu Hijau | C23: Cu concentrate | D23: =CONCATENATE(B23,"_",C23) -> Batu Hijau_Cu concentrate | E23: Electricity and fuel consumption | F23: =SUM(EnergyData_Processed!G27) -> 20950747 | G23: GJ | H23: =VLOOKUP(D23,ProductionData_Processed!$E:$J,5,FALSE) -> 141520.82 | I23: =VLOOKUP(D23,ProductionData_Processed!$E:$L,8,FALSE) -> 0.48923445 | J23: =F23/H23*I23 -> 72.426284 | K23: =SUM(J23:J23) -> 72.426284 | L23: =AVERAGE(K23:K52) -> 36.851768 | M23: =AVERAGE(J23,J24,J26,J28,J30,J32,J34,#REF!,J36,J37,J40,J42,J44,J46,J48,J50) -> #REF!
A24: KAZ Minerals | B24: Bozshakol | C24: Cu concentrate | D24: =CONCATENATE(B24,"_",C24) -> Bozshakol_Cu concentrate | E24: Electricity consumption | F24: =SUM(EnergyData_Processed!G30) -> 3850000 | G24: GJ | H24: =VLOOKUP(D24,ProductionData_Processed!$E:$J,5,FALSE) -> 105000 | I24: =VLOOKUP(D24,ProductionData_Processed!$E:$L,8,FALSE) -> 0.75015588 | J24: =F24/H24*I24 -> 27.505716 | K24: =SUM(J24:J25) -> 37.865011
A25: KAZ Minerals | B25: Bozshakol | C25: Cu concentrate | D25: =CONCATENATE(B25,"_",C25) -> Bozshakol_Cu concentrate | E25: Fuel consumption | F25: =SUM(EnergyData_Processed!G29) -> 1450000 | G25: GJ | H25: =VLOOKUP(D25,ProductionData_Processed!$E:$J,5,FALSE) -> 105000 | I25: =VLOOKUP(D25,ProductionData_Processed!$E:$L,8,FALSE) -> 0.75015588 | J25: =F25/H25*I25 -> 10.359296
A26: KAZ Minerals | B26: Bozymchak | C26: Cu concentrate | D26: =CONCATENATE(B26,"_",C26) -> Bozymchak_Cu concentrate | E26: Electricity consumption | F26: =SUM(EnergyData_Processed!G32) -> 180000 | G26: GJ | H26: =VLOOKUP(D26,ProductionData_Processed!$E:$J,5,FALSE) -> 5000 | I26: =VLOOKUP(D26,ProductionData_Processed!$E:$L,8,FALSE) -> 0.35627853 | J26: =F26/H26*I26 -> 12.826027 | K26: =SUM(J26:J27) -> 22.801826
A27: KAZ Minerals | B27: Bozymchak | C27: Cu concentrate | D27: =CONCATENATE(B27,"_",C27) -> Bozymchak_Cu concentrate | E27: Fuel consumption | F27: =SUM(EnergyData_Processed!G31) -> 140000 | G27: GJ | H27: =VLOOKUP(D27,ProductionData_Processed!$E:$J,5,FALSE) -> 5000 | I27: =VLOOKUP(D27,ProductionData_Processed!$E:$L,8,FALSE) -> 0.35627853 | J27: =F27/H27*I27 -> 9.9757987
A28: Ero Copper | B28: Caraíba | C28: Cu concentrate | D28: =CONCATENATE(B28,"_",C28) -> Caraíba_Cu concentrate | E28: Electricity consumption | F28: =SUM(EnergyData_Processed!G36) -> 863526 | G28: GJ | H28: =VLOOKUP(D28,ProductionData_Processed!$E:$J,5,FALSE) -> 43857 | I28: =VLOOKUP(D28,ProductionData_Processed!$E:$L,8,FALSE) -> 1 | J28: =F28/H28*I28 -> 19.689582 | K28: =SUM(J28:J29) -> 31.912101
A29: Ero Copper | B29: Caraíba | C29: Cu concentrate | D29: =CONCATENATE(B29,"_",C29) -> Caraíba_Cu concentrate | E29: Fuel consumption | F29: =SUM(EnergyData_Processed!G33:G35) -> 536043 | G29: GJ | H29: =VLOOKUP(D29,ProductionData_Processed!$E:$J,5,FALSE) -> 43857 | I29: =VLOOKUP(D29,ProductionData_Processed!$E:$L,8,FALSE) -> 1 | J29: =F29/H29*I29 -> 12.222519
A30: KAZ Minerals | B30: East Region Operations | C30: Cu concentrate | D30: =CONCATENATE(B30,"_",C30) -> East Region Operations_Cu concentrate | E30: Electricity consumption | F30: =SUM(EnergyData_Processed!G38) -> 1490000 | G30: GJ | H30: =VLOOKUP(D30,ProductionData_Processed!$E:$J,5,FALSE) -> 41000 | I30: =VLOOKUP(D30,ProductionData_Processed!$E:$L,8,FALSE) -> 0.59282568 | J30: =F30/H30*I30 -> 21.544153 | K30: =SUM(J30:J31) -> 41.497797
A31: KAZ Minerals | B31: East Region Operations | C31: Cu concentrate | D31: =CONCATENATE(B31,"_",C31) -> East Region Operations_Cu concentrate | E31: Fuel consumption | F31: =SUM(EnergyData_Processed!G37,EnergyData_Processed!G39) -> 1380000 | G31: GJ | H31: =VLOOKUP(D31,ProductionData_Processed!$E:$J,5,FALSE) -> 41000 | I31: =VLOOKUP(D31,ProductionData_Processed!$E:$L,8,FALSE) -> 0.59282568 | J31: =F31/H31*I31 -> 19.953645
A32: Taseko Mines | B32: Gibraltar | C32: Cu concentrate | D32: =CONCATENATE(B32,"_",C32) -> Gibraltar_Cu concentrate | E32: Electricity consumption | F32: =SUM(EnergyData_Processed!G40) -> 1695665 | G32: GJ | H32: =VLOOKUP(D32,ProductionData_Processed!$E:$J,5,FALSE) -> 55791.862 | I32: =VLOOKUP(D32,ProductionData_Processed!$E:$L,8,FALSE) -> 0.95617694 | J32: =F32/H32*I32 -> 29.060794 | K32: =SUM(J32:J33) -> 61.792763
A33: Taseko Mines | B33: Gibraltar | C33: Cu concentrate | D33: =CONCATENATE(B33,"_",C33) -> Gibraltar_Cu concentrate | E33: Fuel consumption | F33: =SUM(EnergyData_Processed!G41:G44) -> 1909874 | G33: GJ | H33: =VLOOKUP(D33,ProductionData_Processed!$E:$J,5,FALSE) -> 55791.862 | I33: =VLOOKUP(D33,ProductionData_Processed!$E:$L,8,FALSE) -> 0.95617694 | J33: =F33/H33*I33 -> 32.731969
A34: 29Metals | B34: Golden Grove | C34: Cu concentrate | D34: =CONCATENATE(B34,"_",C34) -> Golden Grove_Cu concentrate | E34: Electricity consumption | F34: =SUM(EnergyData_Processed!G46) -> 567268.49 | G34: GJ | H34: =VLOOKUP(D34,ProductionData_Processed!$E:$J,5,FALSE) -> 18096 | I34: =VLOOKUP(D34,ProductionData_Processed!$E:$L,8,FALSE) -> 0.46635982 | J34: =F34/H34*I34 -> 14.619321 | K34: =SUM(J34:J35) -> 23.424094
A35: 29Metals | B35: Golden Grove | C35: Cu concentrate | D35: =CONCATENATE(B35,"_",C35) -> Golden Grove_Cu concentrate | E35: Fuel consumption | F35: =SUM(EnergyData_Processed!G45) -> 341648.6 | G35: GJ | H35: =VLOOKUP(D35,ProductionData_Processed!$E:$J,5,FALSE) -> 18096 | I35: =VLOOKUP(D35,ProductionData_Processed!$E:$L,8,FALSE) -> 0.46635982 | J35: =F35/H35*I35 -> 8.8047733
A36: China Gold International | B36: Jiama | C36: Cu concentrate | D36: =CONCATENATE(B36,"_",C36) -> Jiama_Cu concentrate | E36: Electricity and fuel consumption | F36: =EnergyData_Processed!G55 -> 711900 | G36: GJ | H36: =VLOOKUP(D36,ProductionData_Processed!$E:$J,5,FALSE) -> 20051 | I36: =VLOOKUP(D36,ProductionData_Processed!$E:$L,8,FALSE) -> 0.52417446 | J36: =F36/H36*I36 -> 18.610533 | K36: =J36 -> 18.610533
A37: MMG | B37: Las Bambas | C37: Cu concentrate | D37: =CONCATENATE(B37,"_",C37) -> Las Bambas_Cu concentrate | E37: Electricity consumption | F37: =SUM(EnergyData_Processed!G57) -> 4719188 | G37: GJ | H37: =VLOOKUP(D37,ProductionData_Processed!$E:$J,5,FALSE) -> 302033 | I37: =VLOOKUP(D37,ProductionData_Processed!$E:$L,8,FALSE) -> 0.83039061 | J37: =F37/H37*I37 -> 12.97464 | K37: =SUM(J37:J38) -> 32.728472
A38: MMG | B38: Las Bambas | C38: Cu concentrate | D38: =CONCATENATE(B38,"_",C38) -> Las Bambas_Cu concentrate | E38: Fuel consumption | F38: =SUM(EnergyData_Processed!G56) -> 7184943 | G38: GJ | H38: =VLOOKUP(D38,ProductionData_Processed!$E:$J,5,FALSE) -> 302033 | I38: =VLOOKUP(D38,ProductionData_Processed!$E:$L,8,FALSE) -> 0.83039061 | J38: =F38/H38*I38 -> 19.753832
A39: Aeris | B39: North Queensland | C39: Cu concentrate | D39: =CONCATENATE(B39,"_",C39) -> North Queensland_Cu concentrate | E39: Fuel consumption | F39: =SUM(EnergyData_Processed!G58) -> 131511 | G39: GJ | H39: =VLOOKUP(D39,ProductionData_Processed!$E:$J,5,FALSE) -> 6803 | I39: =VLOOKUP(D39,ProductionData_Processed!$E:$L,8,FALSE) -> 0.83459682 | J39: =F39/H39*I39 -> 16.133862 | K39: =J39 -> 16.133862
A40: Atalaya Mining | B40: Riotinto | C40: Cu concentrate | D40: =CONCATENATE(B40,"_",C40) -> Riotinto_Cu concentrate | E40: Electricity consumption | F40: =SUM(EnergyData_Processed!G60) -> 1324181.6 | G40: GJ | H40: =VLOOKUP(D40,ProductionData_Processed!$E:$J,5,FALSE) -> 51667 | I40: =VLOOKUP(D40,ProductionData_Processed!$E:$L,8,FALSE) -> 1 | J40: =F40/H40*I40 -> 25.629156 | K40: =SUM(J40:J41) -> 45.435996
...

Sheet ProductionData_Processed
A1: Company | B1: Production site | C1: Main product | D1: Products | E1: Key | F1: Metric | G1: Initial value | H1: Initial unit | I1: Modified value | J1: Modified unit | K1: Value ($/t) | L1: Allocation factors (%)
A2: Central Asia Metals | B2: Kounrad | C2: =VLOOKUP(B2,EnergyData_Processed!$B$2:$C$102,2,FALSE) -> Cu cathode | D2: Cu cathode | E2: =CONCATENATE(B2,"_",D2) -> Kounrad_Cu cathode | F2: Copper cathode production | G2: 13816 | H2: t | I2: =G2 -> 13816 | J2: t | K2: =I2*Parameters!B11 -> 142760728 | L2: =K2/K2 -> 1
A3: Freeport | B3: Tyrone | C3: =VLOOKUP(B3,EnergyData_Processed!$B$2:$C$102,2,FALSE) -> Cu cathode | D3: Cu cathode | E3: =CONCATENATE(B3,"_",D3) -> Tyrone_Cu cathode | F3: copper production-2023 | G3: 23133 | H3: tonnes | I3: =G3 -> 23133 | J3: t | K3: =I3*Parameters!B11 -> 239033289 | L3: =K3/K3 -> 1
A4: Freeport | B4: El Abra | C4: =VLOOKUP(B4,EnergyData_Processed!$B$2:$C$102,2,FALSE) -> Cu cathode | D4: Cu cathode | E4: =CONCATENATE(B4,"_",D4) -> El Abra_Cu cathode | F4: Copper production | G4: 98429 | H4: tonnes | I4: =G4 -> 98429 | J4: t | K4: =I4*Parameters!B11 -> 1017066857 | L4: =K4/SUM($K$4:$K$7) -> 1
A5: Freeport | B5: El Abra | C5: =VLOOKUP(B5,EnergyData_Processed!$B$2:$C$102,2,FALSE) -> Cu cathode | D5: Au metal | E5: =CONCATENATE(B5,"_",D5) -> El Abra_Au metal | F5: Gold production | G5: 0 | H5: oz | I5: =G5*Parameters!D3 -> 0 | J5: t | K5: =I5*Parameters!B13 -> 0 | L5: =K5/SUM($K$4:$K$7) -> 0
A6: Freeport | B6: El Abra | C6: =VLOOKUP(B6,EnergyData_Processed!$B$2:$C$102,2,FALSE) -> Cu cathode | D6: Mo metal | E6: =CONCATENATE(B6,"_",D6) -> El Abra_Mo metal | F6: Mo production | G6: 0 | H6: tonnes | I6: =G6 -> 0 | J6: t | K6: =I6*Parameters!B21 -> 0 | L6: =K6/SUM($K$4:$K$7) -> 0
A7: Freeport | B7: El Abra | C7: =VLOOKUP(B7,EnergyData_Processed!$B$2:$C$102,2,FALSE) -> Cu cathode | D7: Ag metal | E7: =CONCATENATE(B7,"_",D7) -> El Abra_Ag metal | F7: Silver production | G7: 0 | H7: oz | I7: =G7*Parameters!D3 -> 0 | J7: t | K7: =I7*Parameters!B15 -> 0 | L7: =K7/SUM($K$4:$K$7) -> 0
A8: Freeport | B8: Safford | C8: =VLOOKUP(B8,EnergyData_Processed!$B$2:$C$102,2,FALSE) -> Cu cathode | D8: Cu cathode | E8: =CONCATENATE(B8,"_",D8) -> Safford_Cu cathode | F8: Copper production-2023 | G8: 111130 | H8: tonnes | I8: =G8 -> 111130 | J8: t | K8: =I8*Parameters!B11 -> 1148306290 | L8: =K8/K8 -> 1
A9: MMG | B9: Kinsevere | C9: =VLOOKUP(B9,EnergyData_Processed!$B$2:$C$102,2,FALSE) -> Cu cathode | D9: Co metal | E9: =CONCATENATE(B9,"_",D9) -> Kinsevere_Co metal | F9: Cobalt produced | G9: 105 | H9: tonnes | I9: =G9 -> 105 | J9: t | K9: =I9*Parameters!B23 -> 3284610 | L9: =K9/SUM($K$9:$K$10) -> 0.0071616417
A10: MMG | B10: Kinsevere | C10: =VLOOKUP(B10,EnergyData_Processed!$B$2:$C$102,2,FALSE) -> Cu cathode | D10: Cu cathode | E10: =CONCATENATE(B10,"_",D10) -> Kinsevere_Cu cathode | F10: Copper cathode produced | G10: 44068 | H10: tonnes | I10: =G10 -> 44068 | J10: t | K10: =I10*Parameters!B11 -> 455354644 | L10: =K10/SUM($K$9:$K$10) -> 0.99283836
A11: PT Merdeka | B11: Wetar | C11: =VLOOKUP(B11,EnergyData_Processed!$B$2:$C$102,2,FALSE) -> Cu cathode | D11: Cu cathode | E11: =CONCATENATE(B11,"_",D11) -> Wetar_Cu cathode | F11: Copper cathode produced | G11: 19045 | H11: tons | I11: =G11 -> 19045 | J11: t | K11: =I11*Parameters!B11 -> 196791985 | L11: =K11/K11 -> 1
A12: Aeris | B12: Tritton | C12: =VLOOKUP(B12,EnergyData_Processed!$B$2:$C$102,2,FALSE) -> Cu concentrate | D12: Cu concentrate | E12: =CONCATENATE(B12,"_",D12) -> Tritton_Cu concentrate | F12: Cu concentrate | G12: 19700 | H12: t | I12: =G12 -> 19700 | J12: t | K12: =I12*Parameters!B10 -> 195417696 | L12: =K12/SUM($K$12:$K$14) -> 0.91166101
A13: Aeris | B13: Tritton | C13: =VLOOKUP(B13,EnergyData_Processed!$B$2:$C$102,2,FALSE) -> Cu concentrate | D13: Ag concentrate | E13: =CONCATENATE(B13,"_",D13) -> Tritton_Ag concentrate | F13: Silver prod | G13: 156000 | H13: oz | I13: =G13*Parameters!D3 -> 4.422522 | J13: t | K13: =I13*Parameters!B14 -> 3797177.4 | L13: =K13/SUM($K$12:$K$14) -> 0.01771456
A14: Aeris | B14: Tritton | C14: =VLOOKUP(B14,EnergyData_Processed!$B$2:$C$102,2,FALSE) -> Cu concentrate | D14: Au concentrate | E14: =CONCATENATE(B14,"_",D14) -> Tritton_Au concentrate | F14: Gold produced | G14: 4899 | H14: oz | I14: =G14*Parameters!D3 -> 0.1388842 | J14: t | K14: =I14*Parameters!B12 -> 15138591 | L14: =K14/SUM($K$12:$K$14) -> 0.070624429
A15: Aeris | B15: Jaguar | C15: =VLOOKUP(B15,EnergyData_Processed!$B$2:$C$102,2,FALSE) -> Cu concentrate | D15: Cu concentrate | E15: =CONCATENATE(B15,"_",D15) -> Jaguar_Cu concentrate | F15: Copper Produced | G15: 0.6 | H15: kt | I15: =G15*1000 -> 600 | J15: t | K15: =I15*Parameters!B10 -> 5951808 | L15: =K15/SUM($K$15:$K$18) -> 0.33622809
A16: Aeris | B16: Jaguar | C16: =VLOOKUP(B16,EnergyData_Processed!$B$2:$C$102,2,FALSE) -> Cu concentrate | D16: Zn concentrate | E16: =CONCATENATE(B16,"_",D16) -> Jaguar_Zn concentrate | F16: Zinc Produced | G16: 3.1 | H16: kt | I16: =G16*1000 -> 3100 | J16: t | K16: =I16*Parameters!B16 -> 8469200 | L16: =K16/SUM($K$15:$K$18) -> 0.47843999
A17: Aeris | B17: Jaguar | C17: =VLOOKUP(B17,EnergyData_Processed!$B$2:$C$102,2,FALSE) -> Cu concentrate | D17: Au concentrate | E17: =CONCATENATE(B17,"_",D17) -> Jaguar_Au concentrate | F17: Gold Produced | G17: 0.4 | H17: koz | I17: =G17*1000*Parameters!D3 -> 0.0113398 | J17: t | K17: =I17*Parameters!B12 -> 1236055.6 | L17: =K17/SUM($K$15:$K$18) -> 0.069826953
A18: Aeris | B18: Jaguar | C18: =VLOOKUP(B18,EnergyData_Processed!$B$2:$C$102,2,FALSE) -> Cu concentrate | D18: Ag concentrate | E18: =CONCATENATE(B18,"_",D18) -> Jaguar_Ag concentrate | F18: Silver Produced | G18: 84 | H18: koz | I18: =G18*1000*Parameters!D3 -> 2.381358 | J18: t | K18: =I18*Parameters!B14 -> 2044634 | L18: =K18/SUM($K$15:$K$18) -> 0.11550497
A19: Aeris | B19: North Queensland | C19: =VLOOKUP(B19,EnergyData_Processed!$B$2:$C$102,2,FALSE) -> Cu concentrate | D19: Cu concentrate | E19: =CONCATENATE(B19,"_",D19) -> North Queensland_Cu concentrate | F19: Copper production | G19: 6803 | H19: t | I19: =G19 -> 6803 | J19: t | K19: =I19*Parameters!B10 -> 67483583 | L19: =K19/SUM($K$19:$K$20) -> 0.83459682
A20: Aeris | B20: North Queensland | C20: =VLOOKUP(B20,EnergyData_Processed!$B$2:$C$102,2,FALSE) -> Cu concentrate | D20: Au concentrate | E20: =CONCATENATE(B20,"_",D20) -> North Queensland_Au concentrate | F20: Gold production | G20: 4328 | H20: oz | I20: =G20*Parameters!D3 -> 0.12269664 | J20: t | K20: =I20*Parameters!B12 -> 13374122 | L20: =K20/SUM($K$19:$K$20) -> 0.16540318
A21: Atalaya Mining | B21: Riotinto | C21: =VLOOKUP(B21,EnergyData_Processed!$B$2:$C$102,2,FALSE) -> Cu concentrate | D21: NA | E21: =CONCATENATE(B21,"_",D21) -> Riotinto_NA | F21: Riotinto Processing Plant, Copper concentrate | G21: 249321 | H21: t | I21: =G21 -> 249321 | J21: t | K21: NA | L21: NA
A22: Atalaya Mining | B22: Riotinto | C22: =VLOOKUP(B22,EnergyData_Processed!$B$2:$C$102,2,FALSE) -> Cu concentrate | D22: Cu concentrate | E22: =CONCATENATE(B22,"_",D22) -> Riotinto_Cu concentrate | F22: Riotinto Processing Plant, Copper contained in concentrate | G22: 51667 | H22: t | I22: =G22 -> 51667 | J22: t | K22: =I22*Parameters!B10 -> 5.1252011e+08 | L22: =K22/K22 -> 1
A23: China Gold International | B23: Jiama | C23: =VLOOKUP(B23,EnergyData_Processed!$B$2:$C$102,2,FALSE) -> Cu concentrate | D23: Cu concentrate | E23: =CONCATENATE(B23,"_",D23) -> Jiama_Cu concentrate | F23: Copper production | G23: 20051 | H23: tonnes | I23: =G23 -> 20051 | J23: t | K23: =I23*Parameters!B10 -> 1.988995e+08 | L23: =K23/SUM($K$23:$K$28) -> 0.52417446
A24: China Gold International | B24: Jiama | C24: =VLOOKUP(B24,EnergyData_Processed!$B$2:$C$102,2,FALSE) -> Cu concentrate | D24: Au concentrate | E24: =CONCATENATE(B24,"_",D24) -> Jiama_Au concentrate | F24: Gold production | G24: 19203 | H24: oz | I24: =G24*Parameters!D3 -> 0.54439545 | J24: t | K24: =I24*Parameters!B12 -> 59339940 | L24: =K24/SUM($K$23:$K$28) -> 0.1563829
A25: China Gold International | B25: Jiama | C25: =VLOOKUP(B25,EnergyData_Processed!$B$2:$C$102,2,FALSE) -> Cu concentrate | D25: Mo concentrate | E25: =CONCATENATE(B25,"_",D25) -> Jiama_Mo concentrate | F25: Mo production | G25: 231 | H25: tonnes | I25: =G25 -> 231 | J25: t | K25: =I25*Parameters!B20 -> 10764600 | L25: =K25/SUM($K$23:$K$28) -> 0.02836874
A26: China Gold International | B26: Jiama | C26: =VLOOKUP(B26,EnergyData_Processed!$B$2:$C$102,2,FALSE) -> Cu concentrate | D26: Zn concentrate | E26: =CONCATENATE(B26,"_",D26) -> Jiama_Zn concentrate | F26: Zinc prod-2021 | G26: 4539.3236 | H26: tonnes | I26: =G26 -> 4539.3236 | J26: t | K26: =I26*Parameters!B16 -> 12401432 | L26: =K26/SUM($K$23:$K$28) -> 0.032682404
A27: China Gold International | B27: Jiama | C27: =VLOOKUP(B27,EnergyData_Processed!$B$2:$C$102,2,FALSE) -> Cu concentrate | D27: Pb concentrate | E27: =CONCATENATE(B27,"_",D27) -> Jiama_Pb concentrate | F27: Lead prod-2021 | G27: 9436.2698 | H27: tonnes | I27: =G27 -> 9436.2698 | J27: t | K27: =I27*Parameters!B18 -> 20901338 | L27: =K27/SUM($K$23:$K$28) -> 0.055082829
A28: China Gold International | B28: Jiama | C28: =VLOOKUP(B28,EnergyData_Processed!$B$2:$C$102,2,FALSE) -> Cu concentrate | D28: Ag concentrate | E28: =CONCATENATE(B28,"_",D28) -> Jiama_Ag concentrate | F28: Silver prod-2023 | G28: 3169403 | H28: oz | I28: =G28*Parameters!D3 -> 89.85099 | J28: t | K28: =I28*Parameters!B14 -> 77146060 | L28: =K28/SUM($K$23:$K$28) -> 0.20330867
A29: Ero Copper | B29: Caraíba | C29: =VLOOKUP(B29,EnergyData_Processed!$B$2:$C$102,2,FALSE) -> Cu concentrate | D29: Cu concentrate | E29: =CONCATENATE(B29,"_",D29) -> Caraíba_Cu concentrate | F29: Copper Production | G29: 43857 | H29: tonnes | I29: =G29 -> 43857 | J29: t | K29: =I29*Parameters!B10 -> 4.3504741e+08 | L29: =K29/K29 -> 1
A30: Ero Copper | B30: Tucuma | C30: =VLOOKUP(B30,EnergyData_Processed!$B$2:$C$102,2,FALSE) -> Cu concentrate | D30: Cu concentrate | E30: =CONCATENATE(B30,"_",D30) -> Tucuma_Cu concentrate | F30: Copper, production -2024 | G30: 5156 | H30: tonnes | I30: =G30 -> 5156 | J30: t | K30: =I30*Parameters!B10 -> 51145870 | L30: =K30/K30 -> 1
A31: Freeport | B31: Grasberg | C31: =VLOOKUP(B31,EnergyData_Processed!$B$2:$C$102,2,FALSE) -> Cu concentrate | D31: Cu concentrate | E31: =CONCATENATE(B31,"_",D31) -> Grasberg_Cu concentrate | F31: Copper production-2023 | G31: 752963 | H31: tonnes | I31: =G31 -> 752963 | J31: t | K31: =I31*Parameters!B10 -> 7.469152e+09 | L31: =K31/SUM($K$31:$K$33) -> 0.54365667
A32: Freeport | B32: Grasberg | C32: =VLOOKUP(B32,EnergyData_Processed!$B$2:$C$102,2,FALSE) -> Cu concentrate | D32: Au concentrate | E32: =CONCATENATE(B32,"_",D32) -> Grasberg_Au concentrate | F32: Gold production-2023 | G32: 1978000 | H32: oz | I32: =G32*Parameters!D3 -> 56.075311 | J32: t | K32: =I32*Parameters!B12 -> 6.112295e+09 | L32: =K32/SUM($K$31:$K$33) -> 0.44489521
A33: Freeport | B33: Grasberg | C33: =VLOOKUP(B33,EnergyData_Processed!$B$2:$C$102,2,FALSE) -> Cu concentrate | D33: Ag concentrate | E33: =CONCATENATE(B33,"_",D33) -> Grasberg_Ag concentrate | F33: Silver production -2023 | G33: 6461663.8 | H33: oz | I33: =G33*Parameters!D3 -> 183.18494 | J33: t | K33: =I33*Parameters!B14 -> 1.5728259e+08 | L33: =K33/SUM($K$31:$K$33) -> 0.011448117
A34: KAZ Minerals | B34: Aktogay | C34: =VLOOKUP(B34,EnergyData_Processed!$B$2:$C$102,2,FALSE) -> Cu concentrate & cathode | D34: NA | E34: =CONCATENATE(B34,"_",D34) -> Aktogay_NA | F34: Copper production | G34: 229 | H34: kt | I34: =G34*1000 -> 229000 | J34: t | K34: =I34*Parameters!B10 -> 2271606720 | L34: =K34/SUM($K$34:$K$35) -> 0.92897425
A35: KAZ Minerals | B35: Aktogay | C35: =VLOOKUP(B35,EnergyData_Processed!$B$2:$C$102,2,FALSE) -> Cu concentrate & cathode | D35: Mo concentrate | E35: =CONCATENATE(B35,"_",D35) -> Aktogay_Mo concentrate | F35: Molybdenum production | G35: 3727 | H35: t | I35: =G35 -> 3727 | J35: t | K35: =I35*Parameters!B20 -> 173678200 | L35: =K35/SUM($K$34:$K$35) -> 0.071025752
A36: KAZ Minerals | B36: Bozshakol | C36: =VLOOKUP(B36,EnergyData_Processed!$B$2:$C$102,2,FALSE) -> Cu concentrate | D36: Cu concentrate | E36: =CONCATENATE(B36,"_",D36) -> Bozshakol_Cu concentrate | F36: Copper production | G36: 105 | H36: kt | I36: =G36*1000 -> 105000 | J36: t | K36: =I36*Parameters!B10 -> 1041566400 | L36: =K36/SUM($K$36:$K$39) -> 0.75015588
A37: KAZ Minerals | B37: Bozshakol | C37: =VLOOKUP(B37,EnergyData_Processed!$B$2:$C$102,2,FALSE) -> Cu concentrate | D37: Au concentrate | E37: =CONCATENATE(B37,"_",D37) -> Bozshakol_Au concentrate | F37: Gold production | G37: 104 | H37: koz | I37: =G37*Parameters!D3*1000 -> 2.948348 | J37: t | K37: =I37*Parameters!B12 -> 3.2137446e+08 | L37: =K37/SUM($K$36:$K$39) -> 0.23145998
A38: KAZ Minerals | B38: Bozshakol | C38: =VLOOKUP(B38,EnergyData_Processed!$B$2:$C$102,2,FALSE) -> Cu concentrate | D38: Ag concentrate | E38: =CONCATENATE(B38,"_",D38) -> Bozshakol_Ag concentrate | F38: Silver production | G38: 818000 | H38: oz | I38: =G38*Parameters!D3 -> 23.189891 | J38: t | K38: =I38*Parameters!B14 -> 19910840 | L38: =K38/SUM($K$36:$K$39) -> 0.014340165
A39: KAZ Minerals | B39: Bozshakol | C39: =VLOOKUP(B39,EnergyData_Processed!$B$2:$C$102,2,FALSE) -> Cu concentrate | D39: Mo concentrate | E39: =CONCATENATE(B39,"_",D39) -> Bozshakol_Mo concentrate | F39: Molybdenum production 2020 | G39: 120.4918 | H39: t | I39: =G39 -> 120.4918 | J39: t | K39: =I39*Parameters!B20 -> 5614918 | L39: =K39/SUM($K$36:$K$39) -> 0.0040439705
A40: KAZ Minerals | B40: Bozymchak | C40: =VLOOKUP(B40,EnergyData_Processed!$B$2:$C$102,2,FALSE) -> Cu concentrate | D40: Cu concentrate | E40: =CONCATENATE(B40,"_",D40) -> Bozymchak_Cu concentrate | F40: Copper production | G40: 5 | H40: kt | I40: =G40*1000 -> 5000 | J40: t | K40: =I40*Parameters!B10 -> 49598400 | L40: =K40/SUM($K$40:$K$41) -> 0.35627853
...

Sheet EnergyData_Processed
A1: Company | B1: Production site | C1: Main product | D1: Metric | E1: Initial value | F1: Initial unit | G1: Modified value | H1: Modified unit
A2: Freeport | B2: El Abra | C2: Cu cathode | D2: Indirect Energy Total | E2: 2398 | F2: TERAJOULES | G2: =E2*1000 -> 2398000 | H2: GJ
A3: Freeport | B3: El Abra | C3: Cu cathode | D3: DIESEL consumption | E3: 1110.6 | F3: TERAJOULES | G3: =E3*1000 -> 1110600 | H3: GJ
A4: Freeport | B4: El Abra | C4: Cu cathode | D4: GASOLINE consumption | E4: 5.8 | F4: TERAJOULES | G4: =E4*1000 -> 5800 | H4: GJ
A5: Freeport | B5: El Abra | C5: Cu cathode | D5: PROPANE /LPG consumption | E5: 4.2 | F5: TERAJOULES | G5: =E5*1000 -> 4200 | H5: GJ
A6: MMG | B6: Kinsevere | C6: Cu cathode | D6: Direct energy consumption | E6: 1160907 | F6: GJ | G6: =E6 -> 1160907 | H6: =F6 -> GJ
A7: MMG | B7: Kinsevere | C7: Cu cathode | D7: Indirect energy consumption | E7: 503140 | F7: GJ | G7: =E7 -> 503140 | H7: =F7 -> GJ
A8: Central Asia Metals | B8: Kounrad | C8: Cu cathode | D8: Coal | E8: 247160 | F8: GJ | G8: =E8 -> 247160 | H8: =F8 -> GJ
A9: Central Asia Metals | B9: Kounrad | C9: Cu cathode | D9: Diesel/petroleum | E9: 14316 | F9: GJ | G9: =E9 -> 14316 | H9: =F9 -> GJ
A10: Central Asia Metals | B10: Kounrad | C10: Cu cathode | D10: Electricity from renewables | E10: 2553 | F10: GJ | G10: =E10 -> 2553 | H10: =F10 -> GJ
A11: Central Asia Metals | B11: Kounrad | C11: Cu cathode | D11: Electricity from non-renewables | E11: 209820 | F11: GJ | G11: =E11 -> 209820 | H11: =F11 -> GJ
A12: Freeport | B12: Safford | C12: Cu cathode | D12: Indirect Energy Total | E12: 1392 | F12: TERAJOULES | G12: =E12*1000 -> 1392000 | H12: GJ
A13: Freeport | B13: Safford | C13: Cu cathode | D13: DIESEL consumption | E13: 2857.1 | F13: TERAJOULES | G13: =E13*1000 -> 2857100 | H13: GJ
A14: Freeport | B14: Safford | C14: Cu cathode | D14: GASOLINE consumption | E14: 59.9 | F14: TERAJOULES | G14: =E14*1000 -> 59900 | H14: GJ
A15: Freeport | B15: Safford | C15: Cu cathode | D15: PROPANE /LPG consumption | E15: 28.2 | F15: TERAJOULES | G15: =E15*1000 -> 28200 | H15: GJ
A16: Freeport | B16: Tyrone | C16: Cu cathode | D16: Indirect Energy Total | E16: 764 | F16: TERAJOULES | G16: =E16*1000 -> 764000 | H16: GJ
A17: Freeport | B17: Tyrone | C17: Cu cathode | D17: DIESEL consumption | E17: 584 | F17: TERAJOULES | G17: =E17*1000 -> 584000 | H17: GJ
A18: Freeport | B18: Tyrone | C18: Cu cathode | D18: B20 BIODIESEL consumption | E18: 7.5 | F18: TERAJOULES | G18: =E18*1000 -> 7500 | H18: GJ
A19: Freeport | B19: Tyrone | C19: Cu cathode | D19: GASOLINE consumption | E19: 18.3 | F19: TERAJOULES | G19: =E19*1000 -> 18300 | H19: GJ
A20: Freeport | B20: Tyrone | C20: Cu cathode | D20: NATURAL GAS consumption | E20: 21.1 | F20: TERAJOULES | G20: =E20*1000 -> 21100 | H20: GJ
A21: Freeport | B21: Tyrone | C21: Cu cathode | D21: PROPANE /LPG consumption | E21: 2.7 | F21: TERAJOULES | G21: =E21*1000 -> 2700 | H21: GJ
A22: PT Merdeka | B22: Wetar | C22: Cu cathode | D22: Electricity | E22: 62928340 | F22: kWh | G22: =E22*Parameters!D2 -> 226542.02 | H22: GJ
A23: PT Merdeka | B23: Wetar | C23: Cu cathode | D23: Gasoline | E23: 696.72 | F23: gigaJoule | G23: =E23 -> 696.72 | H23: GJ
A24: PT Merdeka | B24: Wetar | C24: Cu cathode | D24: Diesel B30 | E24: 553955.97 | F24: gigaJoule | G24: =E24 -> 553955.97 | H24: GJ
A25: KAZ Minerals | B25: Aktogay | C25: Cu concentrate & cathode | D25: Diesel consumption | E25: 1.43 | F25: PJ | G25: =E25*1000000 -> 1430000 | H25: GJ
A26: KAZ Minerals | B26: Aktogay | C26: Cu concentrate & cathode | D26: Electricity consumption | E26: 7.02 | F26: PJ | G26: =E26*1000000 -> 7020000 | H26: GJ
A27: PT Amman | B27: Batu Hijau | C27: Cu concentrate | D27: Energy Consumption | E27: 20950747 | F27: GJ | G27: =E27 -> 20950747 | H27: =F27 -> GJ
A28: PT Amman | B28: Batu Hijau | C28: Cu concentrate | D28: 35% of B35Biodiesel consumption | E28: 0 | F28: Gigajoules (GJ) | G28: =E28 -> 0 | H28: GJ
A29: KAZ Minerals | B29: Bozshakol | C29: Cu concentrate | D29: Diesel consumption | E29: 1.45 | F29: PJ | G29: =E29*1000000 -> 1450000 | H29: GJ
A30: KAZ Minerals | B30: Bozshakol | C30: Cu concentrate | D30: Electricity consumption | E30: 3.85 | F30: PJ | G30: =E30*1000000 -> 3850000 | H30: GJ
A31: KAZ Minerals | B31: Bozymchak | C31: Cu concentrate | D31: Diesel consumption | E31: 0.14 | F31: PJ | G31: =E31*1000000 -> 140000 | H31: GJ
A32: KAZ Minerals | B32: Bozymchak | C32: Cu concentrate | D32: Electricity consumption | E32: 0.18 | F32: PJ | G32: =E32*1000000 -> 180000 | H32: GJ
A33: Ero Copper | B33: Caraíba | C33: Cu concentrate | D33: Diesel | E33: 530762 | F33: GJ | G33: =E33 -> 530762 | H33: =F33 -> GJ
A34: Ero Copper | B34: Caraíba | C34: Cu concentrate | D34: Gasoline | E34: 4644 | F34: GJ | G34: =E34 -> 4644 | H34: =F34 -> GJ
A35: Ero Copper | B35: Caraíba | C35: Cu concentrate | D35: Liquified petroleum gas LPG | E35: 637 | F35: GJ | G35: =E35 -> 637 | H35: =F35 -> GJ
A36: Ero Copper | B36: Caraíba | C36: Cu concentrate | D36: Electricity | E36: 863526 | F36: GJ | G36: =E36 -> 863526 | H36: =F36 -> GJ
A37: KAZ Minerals | B37: East Region Operations | C37: Cu concentrate | D37: Diesel consumption | E37: 0.26 | F37: PJ | G37: =E37*1000000 -> 260000 | H37: GJ
A38: KAZ Minerals | B38: East Region Operations | C38: Cu concentrate | D38: Electricity consumption | E38: 1.49 | F38: PJ | G38: =E38*1000000 -> 1490000 | H38: GJ
A39: KAZ Minerals | B39: East Region Operations | C39: Cu concentrate | D39: Heat consumption | E39: 1.12 | F39: PJ | G39: =E39*1000000 -> 1120000 | H39: GJ
A40: Taseko Mines | B40: Gibraltar | C40: Cu concentrate | D40: Grid Electricity Consumption | E40: 1695665 | F40: GJ | G40: =E40 -> 1695665 | H40: GJ
...

Sheet RawData
A1: Company | B1: Production site | C1: Type of metric | D1: Metric | E1: Value | F1: Unit
A2: Aeris | B2: Tritton | C2: Energy | D2: Diesel consumption | E2: 338743 | F2: GJ
A3: Aeris | B3: Tritton | C3: Energy | D3: Electricity consumption | E3: 302270 | F3: GJ
A4: Aeris | B4: Tritton | C4: Production | D4: Cu concentrate | E4: 19700 | F4: t
A5: Aeris | B5: Tritton | C5: Production | D5: Silver prod | E5: 156 000 | F5: oz
A6: Aeris | B6: Tritton | C6: Production | D6: Gold produced | E6: 4899 | F6: oz
A7: Aeris | B7: Jaguar | C7: Energy | D7: Diesel consumption | E7: 22534 | F7: GJ
A8: Aeris | B8: Jaguar | C8: Energy | D8: Natural Gas consumption | E8: 194788 | F8: GJ
A9: Aeris | B9: Jaguar | C9: Production | D9: Copper Produced | E9: 0.6 | F9: kt
A10: Aeris | B10: Jaguar | C10: Production | D10: Zinc Produced | E10: 3.1 | F10: kt
A11: Aeris | B11: Jaguar | C11: Production | D11: Gold Produced | E11: 0.4 | F11: koz
A12: Aeris | B12: Jaguar | C12: Production | D12: Silver Produced | E12: 84 | F12: koz
A13: Aeris | B13: North Queensland | C13: Energy | D13: Diesel consumption | E13: 131511 | F13: GJ
A14: Aeris | B14: North Queensland | C14: Production | D14: Copper production | E14: 6900 | F14: t
A15: Aeris | B15: North Queensland | C15: Production | D15: Gold production | E15: 4328 | F15: oz
A16: Atalaya Mining | B16: Riotinto | C16: Energy | D16: Total energy of fuel consumption | E16: 25584 | F16: m3
A17: Atalaya Mining | B17: Riotinto | C17: Energy | D17: Total electricity consumption within the organisation | E17: 367828225 | F17: Kwh
A18: Atalaya Mining | B18: Riotinto | C18: Production | D18: Riotinto Processing Plant, Copper concentrate | E18: 249321 | F18: t
A19: Atalaya Mining | B19: Riotinto | C19: Production | D19: Riotinto Processing Plant, Copper contained in concentrate | E19: 51667 | F19: t
A20: Capstone | B20: Pinto Valley | C20: Energy | D20: Fuel | E20: 1430653 | F20: GJ
A21: Capstone | B21: Pinto Valley | C21: Energy | D21: Electricity | E21: 1201840 | F21: GJ
A22: Capstone | B22: Pinto Valley | C22: Production | D22: Copper Concentrate Produced-2022 | E22: 54222 | F22: tonnes
A23: Capstone | B23: Pinto Valley | C23: Production | D23: Copper Cathode Produced-2022 | E23: 2622 | F23: tonnes
A24: Capstone | B24: Pinto Valley | C24: Production | D24: Molybdenum production 2022 | E24: 86.305881 | F24: tonnes
A25: Capstone | B25: Mantos Blancos | C25: Energy | D25: Fuel | E25: 1859277 | F25: GJ
A26: Capstone | B26: Mantos Blancos | C26: Energy | D26: Electricity | E26: 863004 | F26: GJ
A27: Capstone | B27: Mantos Blancos | C27: Production | D27: Copper Concentrate Produced-2022 | E27: 34961 | F27: tonnes
A28: Capstone | B28: Mantos Blancos | C28: Production | D28: Copper Cathode Produced-2022 | E28: 15697 | F28: tonnes
A29: Capstone | B29: Mantos Blancos | C29: Production | D29: Silver production-2022 | E29: 980000 | F29: oz
A30: Capstone | B30: Mantoverde | C30: Energy | D30: Fuel | E30: 2101672 | F30: GJ
A31: Capstone | B31: Mantoverde | C31: Energy | D31: Electricity | E31: 691918 | F31: GJ
A32: Capstone | B32: Mantoverde | C32: Production | D32: Copper Cathode Produced-2022 | E32: 47364 | F32: tonnes
A33: Capstone | B33: Mantoverde | C33: Production | D33: Gold production -2024 | E33: 5810.6007 | F33: oz
A34: Capstone | B34: Cozamin | C34: Energy | D34: Fuel | E34: 167855 | F34: GJ
A35: Capstone | B35: Cozamin | C35: Energy | D35: Electricity | E35: 228707 | F35: GJ
A36: Capstone | B36: Cozamin | C36: Production | D36: Copper Cathode Produced-2022 | E36: 24451 | F36: tonnes
A37: Capstone | B37: Cozamin | C37: Production | D37: Zinc production | E37: 770 | F37: tonnes
A38: Capstone | B38: Cozamin | C38: Production | D38: Silver production | E38: 1 376 000 | F38: OZ
A39: Central Asia Metals | B39: Kounrad | C39: Energy | D39: Coal | E39: 247160 | F39: GJ
A40: Central Asia Metals | B40: Kounrad | C40: Energy | D40: Diesel/petroleum | E40: 14316 | F40: GJ
...

Sheet Parameters
A1: Conversion factors
A2: General | B2: 1 | C2: kWh | D2: 0.0036 | E2: GJ
A3: General | B3: 1 | C3: oz | D3: 2.83495e-05 | E3: t
A4: General | B4: 1 | C4: lb | D4: 0.45359237 | E4: kg
A5: Diesel | B5: 1 | C5: L | D5: 38.6 | E5: MJ | F5: Source | G5: https://kerone.com/pdf/calorific-value-of-higher-and-lower-heating.pdf
A6: Diesel | B6: 1 | C6: t | D6: 1.14 | E6: m3 | F6: Source | G6: https://www.engineeringtoolbox.com/fuels-densities-specific-volumes-d_166.html
A7: Diesel | B7: 1 | C7: kg | D7: 45.6 | E7: MJ | F7: Source | G7: https://kerone.com/pdf/calorific-value-of-higher-and-lower-heating.pdf
A9: Prices
A10: Cu concentrate | B10: 9919.68 | C10: $/t Cu content | E10: Source | F10: https://www.metal.com/Copper/202507310001
A11: Cu cathode | B11: 10333 | C11: $/t Cu content | E11: Source | F11: https://www.metal.com/Copper/201102250170
A12: Au concentrate | B12: 1.0900154e+08 | C12: $/t Au content | E12: Source | F12: Estimation based on Au metal price
A13: Au metal | B13: 121112817 | C13: $/t Au content | E13: Source | F13: https://www.metal.com/Gold/201102250531
A14: Ag concentrate | B14: 858600 | C14: $/t Ag content | E14: Source | F14: Estimation based on Ag metal price
A15: Ag metal | B15: 954000 | C15: $/t Ag content | E15: Source | F15: https://www.metal.com/Silver/201102250524
A16: Zn concentrate | B16: 2732 | C16: $/t Zn content | E16: Source | F16: https://www.metal.com/Zinc/201312030008
A17: Zn metal | B17: 3163 | C17: $/t Zn content | E17: Source | F17: https://www.metal.com/Zinc/201102250173
A18: Pb concentrate | B18: 2215 | C18: $/t Pb content | E18: Source | F18: https://www.metal.com/Lead/201312030006
A19: Pb metal | B19: 2305 | C19: $/t Pb content | E19: Source | F19: https://www.metal.com/Lead/201102250211
A20: Mo concentrate | B20: 46600 | C20: $/t Mo content | E20: Source | F20: https://www.metal.com/Other-Minor-Metals/201102250481
A21: Mo metal | B21: 61100 | C21: $/t Mo content | E21: Source | F21: https://www.metal.com/Other-Minor-Metals/202107140001
... A23: Co metal | B23: 31282 | C23: $/t Co content | E23: Source | F23: https://www.metal.com/Cobalt/201102250375
